<?xml version="1.0" ?>
<!-- =================================================================================== -->
<!-- |    This document was autogenerated by xacro from /home/giang/Workspace/eco_ws/wsp/src/construction_vehicles/mining_excavator/description/urdf/mining_excavator.urdf.xacro | -->
<!-- |    EDITING THIS FILE BY HAND IS NOT RECOMMENDED                                 | -->
<!-- =================================================================================== -->
<robot name="mining_excavator">
  <link name="Cat_6015B_Base">
    <visual>
      <geometry>
        <mesh filename="package://construction_vehicles/mining_excavator/description/meshes/visual/Base.dae"/>
      </geometry>
    </visual>
  </link>
  <joint name="Cat_6015B_TrackLeft_Joint" type="fixed">
    <origin rpy="0 0 0" xyz="0 0 0"/>
    <parent link="Cat_6015B_Base"/>
    <child link="Cat_6015B_TrackLeft"/>
  </joint>
  <link name="Cat_6015B_TrackLeft">
    <visual>
      <geometry>
        <mesh filename="package://construction_vehicles/mining_excavator/description/meshes/visual/TrackLeft.dae"/>
      </geometry>
    </visual>
  </link>
  <joint name="Cat_6015B_TrackRight_Joint" type="fixed">
    <origin rpy="0 0 0" xyz="0 0 0"/>
    <parent link="Cat_6015B_Base"/>
    <child link="Cat_6015B_TrackRight"/>
  </joint>
  <link name="Cat_6015B_TrackRight">
    <visual>
      <geometry>
        <mesh filename="package://construction_vehicles/mining_excavator/description/meshes/visual/TrackRight.dae"/>
      </geometry>
    </visual>
  </link>
  <joint name="Cat_6015B_WheelLeft_Joint" type="continuous">
    <origin rpy="0 0 0" xyz="0.793869 1.89112 0.812398"/>
    <parent link="Cat_6015B_Base"/>
    <child link="Cat_6015B_WheelLeft"/>
    <axis xyz="0 1 0"/>
  </joint>
  <link name="Cat_6015B_WheelLeft">
    <visual>
      <geometry>
        <mesh filename="package://construction_vehicles/mining_excavator/description/meshes/visual/Wheel.dae"/>
      </geometry>
    </visual>
  </link>
  <joint name="Cat_6015B_WheelRight_Joint" type="continuous">
    <origin rpy="0 0 0" xyz="0.793869 -1.89112 0.812398"/>
    <parent link="Cat_6015B_Base"/>
    <child link="Cat_6015B_WheelRight"/>
    <axis xyz="0 1 0"/>
  </joint>
  <link name="Cat_6015B_WheelRight">
    <visual>
      <geometry>
        <mesh filename="package://construction_vehicles/mining_excavator/description/meshes/visual/Wheel.dae"/>
      </geometry>
    </visual>
  </link>
  <joint name="Cat_6015B_MotorLeft_Joint" type="continuous">
    <origin rpy="0 0 0" xyz="-4.76455 1.89112 0.80984"/>
    <parent link="Cat_6015B_Base"/>
    <child link="Cat_6015B_MotorLeft"/>
    <axis xyz="0 1 0"/>
  </joint>
  <link name="Cat_6015B_MotorLeft">
    <visual>
      <geometry>
        <mesh filename="package://construction_vehicles/mining_excavator/description/meshes/visual/MotorLeft.dae"/>
      </geometry>
    </visual>
  </link>
  <joint name="Cat_6015B_MotorRight_Joint" type="continuous">
    <origin rpy="0 0 0" xyz="-4.76455 -1.89112 0.80984"/>
    <parent link="Cat_6015B_Base"/>
    <child link="Cat_6015B_MotorRight"/>
    <axis xyz="0 1 0"/>
  </joint>
  <link name="Cat_6015B_MotorRight">
    <visual>
      <geometry>
        <mesh filename="package://construction_vehicles/mining_excavator/description/meshes/visual/MotorRight.dae"/>
      </geometry>
    </visual>
  </link>
  <joint name="Cat_6015B_Cabin_Joint" type="revolute">
    <origin rpy="0 0 0" xyz="-1.96792 0 0"/>
    <parent link="Cat_6015B_Base"/>
    <child link="Cat_6015B_Cabin"/>
    <axis xyz="0 0 1"/>
    <limit effort="1000.0" lower="-3.141592653589793" upper="3.141592653589793" velocity="1000.0"/>
  </joint>
  <link name="Cat_6015B_Cabin">
    <visual>
      <geometry>
        <mesh filename="package://construction_vehicles/mining_excavator/description/meshes/visual/CabinNoWires.dae"/>
      </geometry>
    </visual>
  </link>
  <joint name="Cat_6015B_Boom_Joint" type="continuous">
    <origin rpy="0 0 0" xyz="0.759 0 3.73919"/>
    <parent link="Cat_6015B_Cabin"/>
    <child link="Cat_6015B_Boom"/>
    <axis xyz="0 1 0"/>
  </joint>
  <link name="Cat_6015B_Boom">
    <visual>
      <geometry>
        <mesh filename="package://construction_vehicles/mining_excavator/description/meshes/visual/BoomNoWires.dae"/>
      </geometry>
    </visual>
  </link>
  <joint name="Cat_6015B_BoomCylinder_Joint" type="continuous">
    <origin rpy="0 0.6846996468743834 0" xyz="1.844 0 2.46739"/>
    <parent link="Cat_6015B_Cabin"/>
    <child link="Cat_6015B_BoomCylinder"/>
    <axis xyz="0 1 0"/>
  </joint>
  <link name="Cat_6015B_BoomCylinder">
    <visual>
      <geometry>
        <mesh filename="package://construction_vehicles/mining_excavator/description/meshes/visual/BoomCylinderNoWiresLeft.dae"/>
      </geometry>
    </visual>
    <visual>
      <geometry>
        <mesh filename="package://construction_vehicles/mining_excavator/description/meshes/visual/BoomCylinderNoWiresRight.dae"/>
      </geometry>
    </visual>
  </link>
  <joint name="Cat_6015B_BoomPiston_Joint" type="prismatic">
    <origin rpy="0 0 0" xyz="0 0 4.855"/>
    <parent link="Cat_6015B_BoomCylinder"/>
    <child link="Cat_6015B_BoomPiston"/>
    <axis xyz="0 0 1"/>
    <limit effort="1000.0" lower="-1.63" upper="0.27" velocity="1000.0"/>
  </joint>
  <link name="Cat_6015B_BoomPiston">
    <visual>
      <geometry>
        <mesh filename="package://construction_vehicles/mining_excavator/description/meshes/visual/BoomPistonLeft.dae"/>
      </geometry>
    </visual>
    <visual>
      <geometry>
        <mesh filename="package://construction_vehicles/mining_excavator/description/meshes/visual/BoomPistonRight.dae"/>
      </geometry>
    </visual>
  </link>
  <joint name="Cat_6015B_Arm_Joint" type="continuous">
    <origin rpy="0 0 0" xyz="7.343 0 1.768"/>
    <parent link="Cat_6015B_Boom"/>
    <child link="Cat_6015B_Arm"/>
    <axis xyz="0 1 0"/>
  </joint>
  <link name="Cat_6015B_Arm">
    <visual>
      <geometry>
        <mesh filename="package://construction_vehicles/mining_excavator/description/meshes/visual/Arm.dae"/>
      </geometry>
    </visual>
  </link>
  <joint name="Cat_6015B_ArmCylinder_Joint" type="continuous">
    <origin rpy="0 0.03457462341615727 0" xyz="3.381 0 3.303"/>
    <parent link="Cat_6015B_Boom"/>
    <child link="Cat_6015B_ArmCylinder"/>
    <axis xyz="0 1 0"/>
  </joint>
  <link name="Cat_6015B_ArmCylinder">
    <visual>
      <geometry>
        <mesh filename="package://construction_vehicles/mining_excavator/description/meshes/visual/ArmCylinder.dae"/>
      </geometry>
    </visual>
  </link>
  <joint name="Cat_6015B_ArmPiston_Joint" type="prismatic">
    <origin rpy="0 0 0" xyz="4.855 0 0"/>
    <parent link="Cat_6015B_ArmCylinder"/>
    <child link="Cat_6015B_ArmPiston"/>
    <axis xyz="1 0 0"/>
    <limit effort="1000.0" lower="-1.63" upper="0.3" velocity="1000.0"/>
  </joint>
  <link name="Cat_6015B_ArmPiston">
    <visual>
      <geometry>
        <mesh filename="package://construction_vehicles/mining_excavator/description/meshes/visual/ArmPiston.dae"/>
      </geometry>
    </visual>
  </link>
  <joint name="Cat_6015B_Bucket_Joint" type="continuous">
    <origin rpy="0 0 0" xyz="-0.087 0 -3.372"/>
    <parent link="Cat_6015B_Arm"/>
    <child link="Cat_6015B_Bucket"/>
    <axis xyz="0 1 0"/>
  </joint>
  <link name="Cat_6015B_Bucket">
    <visual>
      <geometry>
        <mesh filename="package://construction_vehicles/mining_excavator/description/meshes/visual/Bucket.dae"/>
      </geometry>
    </visual>
  </link>
  <joint name="Cat_6015B_BucketCylinder_Joint" type="continuous">
    <origin rpy="0 0.16331551956394022 0" xyz="1.760 0 0.779"/>
    <parent link="Cat_6015B_Arm"/>
    <child link="Cat_6015B_BucketCylinder"/>
    <axis xyz="0 1 0"/>
  </joint>
  <link name="Cat_6015B_BucketCylinder">
    <visual>
      <geometry>
        <mesh filename="package://construction_vehicles/mining_excavator/description/meshes/visual/BucketCylinder.dae"/>
      </geometry>
    </visual>
  </link>
  <joint name="Cat_6015B_BucketPiston_Joint" type="prismatic">
    <origin rpy="0 0 0" xyz="0 0 -3.668"/>
    <parent link="Cat_6015B_BucketCylinder"/>
    <child link="Cat_6015B_BucketPiston"/>
    <axis xyz="0 0 -1"/>
    <limit effort="1000.0" lower="-1.15" upper="0.27" velocity="1000.0"/>
  </joint>
  <link name="Cat_6015B_BucketPiston">
    <visual>
      <geometry>
        <mesh filename="package://construction_vehicles/mining_excavator/description/meshes/visual/BucketPiston.dae"/>
      </geometry>
    </visual>
  </link>
  <joint name="Cat_6015B_BucketPart1_Joint" type="continuous">
    <origin rpy="0 0 0" xyz="0.010 0 -2.721"/>
    <parent link="Cat_6015B_Arm"/>
    <child link="Cat_6015B_BucketPart1"/>
    <axis xyz="0 1 0"/>
  </joint>
  <link name="Cat_6015B_BucketPart1">
    <visual>
      <geometry>
        <mesh filename="package://construction_vehicles/mining_excavator/description/meshes/visual/BucketPart1.dae"/>
      </geometry>
    </visual>
  </link>
  <joint name="Cat_6015B_BucketPart2_Joint" type="continuous">
    <origin rpy="0 0 0" xyz="0.800 0 -0.285"/>
    <parent link="Cat_6015B_Bucket"/>
    <child link="Cat_6015B_BucketPart2"/>
    <axis xyz="0 1 0"/>
  </joint>
  <link name="Cat_6015B_BucketPart2">
    <visual>
      <geometry>
        <mesh filename="package://construction_vehicles/mining_excavator/description/meshes/visual/BucketPart2.dae"/>
      </geometry>
    </visual>
  </link>
</robot>

