<?xml version="1.0" ?>
<!-- =================================================================================== -->
<!-- |    This document was autogenerated by xacro from /home/giang/Workspace/mujoco_ws/src/construction_vehicles/loader/description/urdf/loader.urdf.xacro | -->
<!-- |    EDITING THIS FILE BY HAND IS NOT RECOMMENDED                                 | -->
<!-- =================================================================================== -->
<robot name="loader">
  <link name="Cat_982XE_P01">
    <visual>
      <origin rpy="0 0 0" xyz="-1.9413 0.0 0.751704"/>
      <geometry>
        <mesh filename="package://construction_vehicles/loader/description/meshes/visual/P01.dae"/>
      </geometry>
    </visual>
    <collision>
      <origin rpy="0 0 0" xyz="-1.9413 0.0 0.751704"/>
      <geometry>
        <mesh filename="package://construction_vehicles/loader/description/meshes/collision/P01.stl"/>
      </geometry>
    </collision>
    <inertial>
      <mass value="1000.0"/>
      <inertia ixx="100.0" ixy="0.0" ixz="0.0" iyy="100.0" iyz="0.0" izz="100.0"/>
    </inertial>
  </link>
  <joint name="Cat_982XE_P02_Joint" type="revolute">
    <origin rpy="0 0 0" xyz="-0.717144 0.0 1.33191"/>
    <parent link="Cat_982XE_P01"/>
    <child link="Cat_982XE_P02"/>
    <axis xyz="0 0 1"/>
    <limit effort="1000.0" lower="-0.7853981633974483" upper="0.7853981633974483" velocity="1000.0"/>
  </joint>
  <link name="Cat_982XE_P02">
    <visual>
      <geometry>
        <mesh filename="package://construction_vehicles/loader/description/meshes/visual/P02.dae"/>
      </geometry>
    </visual>
    <collision>
      <geometry>
        <mesh filename="package://construction_vehicles/loader/description/meshes/collision/P02.stl"/>
      </geometry>
    </collision>
    <inertial>
      <mass value="1000.0"/>
      <inertia ixx="100.0" ixy="0.0" ixz="0.0" iyy="100.0" iyz="0.0" izz="100.0"/>
    </inertial>
  </link>
  <joint name="Cat_982XE_P03_Joint" type="continuous">
    <origin rpy="0 0 0" xyz="0.83742 0.0 0.97936"/>
    <parent link="Cat_982XE_P02"/>
    <child link="Cat_982XE_P03"/>
    <axis xyz="0 1 0"/>
  </joint>
  <link name="Cat_982XE_P03">
    <visual>
      <geometry>
        <mesh filename="package://construction_vehicles/loader/description/meshes/visual/P03.dae"/>
      </geometry>
    </visual>
    <collision>
      <geometry>
        <mesh filename="package://construction_vehicles/loader/description/meshes/collision/P03.stl"/>
      </geometry>
    </collision>
    <inertial>
      <mass value="1000.0"/>
      <inertia ixx="100.0" ixy="0.0" ixz="0.0" iyy="100.0" iyz="0.0" izz="100.0"/>
    </inertial>
  </link>
  <joint name="Cat_982XE_P04_Joint" type="fixed">
    <origin rpy="0 0 0" xyz="0.83742 0.0 0.97936"/>
    <parent link="Cat_982XE_P02"/>
    <child link="Cat_982XE_P04"/>
  </joint>
  <link name="Cat_982XE_P04">
    <visual>
      <geometry>
        <mesh filename="package://construction_vehicles/loader/description/meshes/visual/P04.dae"/>
      </geometry>
    </visual>
    <collision>
      <geometry>
        <mesh filename="package://construction_vehicles/loader/description/meshes/collision/P04.stl"/>
      </geometry>
    </collision>
    <inertial>
      <mass value="1000.0"/>
      <inertia ixx="100.0" ixy="0.0" ixz="0.0" iyy="100.0" iyz="0.0" izz="100.0"/>
    </inertial>
  </link>
  <joint name="Cat_982XE_P05_Joint" type="continuous">
    <origin rpy="0 -0.03316125578789226 0" xyz="1.264 0.0 1.0108"/>
    <parent link="Cat_982XE_P02"/>
    <child link="Cat_982XE_P05"/>
    <axis xyz="0 1 0"/>
  </joint>
  <link name="Cat_982XE_P05">
    <visual>
      <geometry>
        <mesh filename="package://construction_vehicles/loader/description/meshes/visual/P05.dae"/>
      </geometry>
    </visual>
    <collision>
      <origin rpy="0 1.5707963267948966 0" xyz="0.554138 0.265697 0.0"/>
      <geometry>
        <cylinder length="1.262766" radius="0.130486"/>
      </geometry>
    </collision>
    <collision>
      <origin rpy="0 1.5707963267948966 0" xyz="0.554138 -0.265697 0.0"/>
      <geometry>
        <cylinder length="1.262766" radius="0.130486"/>
      </geometry>
    </collision>
    <inertial>
      <mass value="1000.0"/>
      <inertia ixx="100.0" ixy="0.0" ixz="0.0" iyy="100.0" iyz="0.0" izz="100.0"/>
    </inertial>
  </link>
  <joint name="Cat_982XE_P06_Joint" type="prismatic">
    <origin rpy="0 0 0" xyz="0.88164 0.0 0.0"/>
    <parent link="Cat_982XE_P05"/>
    <child link="Cat_982XE_P06"/>
    <axis xyz="1 0 0"/>
    <limit effort="1000.0" lower="-0.5" upper="0.04" velocity="1000.0"/>
  </joint>
  <link name="Cat_982XE_P06">
    <visual>
      <geometry>
        <mesh filename="package://construction_vehicles/loader/description/meshes/visual/P06.dae"/>
      </geometry>
    </visual>
    <collision>
      <origin rpy="0 1.5707963267948966 0" xyz="0.550058 0.265697 0.0"/>
      <geometry>
        <cylinder length="1.137294" radius="0.121951"/>
      </geometry>
    </collision>
    <collision>
      <origin rpy="0 1.5707963267948966 0" xyz="0.550058 -0.265697 0.0"/>
      <geometry>
        <cylinder length="1.137294" radius="0.121951"/>
      </geometry>
    </collision>
    <inertial>
      <mass value="1000.0"/>
      <inertia ixx="100.0" ixy="0.0" ixz="0.0" iyy="100.0" iyz="0.0" izz="100.0"/>
    </inertial>
  </link>
  <joint name="Cat_982XE_P07_Joint" type="continuous">
    <origin rpy="0 -0.7365289443416071 0" xyz="0.39609 0.0 -0.47872"/>
    <parent link="Cat_982XE_P02"/>
    <child link="Cat_982XE_P07"/>
    <axis xyz="0 1 0"/>
  </joint>
  <link name="Cat_982XE_P07">
    <visual>
      <geometry>
        <mesh filename="package://construction_vehicles/loader/description/meshes/visual/P07.dae"/>
      </geometry>
    </visual>
    <collision>
      <origin rpy="0 1.5707963267948966 0" xyz="0.426266 0.489167 0.0"/>
      <geometry>
        <cylinder length="0.968702" radius="0.121951"/>
      </geometry>
    </collision>
    <collision>
      <origin rpy="0 1.5707963267948966 0" xyz="0.426266 -0.489167 0.0"/>
      <geometry>
        <cylinder length="0.968702" radius="0.078821"/>
      </geometry>
    </collision>
    <inertial>
      <mass value="1000.0"/>
      <inertia ixx="100.0" ixy="0.0" ixz="0.0" iyy="100.0" iyz="0.0" izz="100.0"/>
    </inertial>
  </link>
  <joint name="Cat_982XE_P08_Joint" type="prismatic">
    <origin rpy="0 0 0" xyz="1.4591 0.0 0.0"/>
    <parent link="Cat_982XE_P07"/>
    <child link="Cat_982XE_P08"/>
    <axis xyz="1 0 0"/>
    <limit effort="1000.0" lower="-0.43" upper="0.43" velocity="1000.0"/>
  </joint>
  <link name="Cat_982XE_P08">
    <visual>
      <geometry>
        <mesh filename="package://construction_vehicles/loader/description/meshes/visual/P08.dae"/>
      </geometry>
    </visual>
    <collision>
      <origin rpy="0 1.5707963267948966 0" xyz="-0.245586 0.487527 0.0"/>
      <geometry>
        <cylinder length="0.645934" radius="0.043654"/>
      </geometry>
    </collision>
    <collision>
      <origin rpy="0 1.5707963267948966 0" xyz="-0.245586 -0.487527 0.0"/>
      <geometry>
        <cylinder length="0.645934" radius="0.043654"/>
      </geometry>
    </collision>
    <inertial>
      <mass value="1000.0"/>
      <inertia ixx="100.0" ixy="0.0" ixz="0.0" iyy="100.0" iyz="0.0" izz="100.0"/>
    </inertial>
  </link>
  <joint name="Cat_982XE_P09_Joint" type="fixed">
    <origin rpy="0 0 0" xyz="1.5113 0.0 -0.66341"/>
    <parent link="Cat_982XE_P03"/>
    <child link="Cat_982XE_P09"/>
  </joint>
  <link name="Cat_982XE_P09">
    <visual>
      <geometry>
        <mesh filename="package://construction_vehicles/loader/description/meshes/visual/P09.dae"/>
      </geometry>
    </visual>
    <collision>
      <geometry>
        <mesh filename="package://construction_vehicles/loader/description/meshes/collision/P09.stl"/>
      </geometry>
    </collision>
    <inertial>
      <mass value="1000.0"/>
      <inertia ixx="100.0" ixy="0.0" ixz="0.0" iyy="100.0" iyz="0.0" izz="100.0"/>
    </inertial>
  </link>
  <joint name="Cat_982XE_P010_Joint" type="continuous">
    <origin rpy="0 0 0" xyz="0.66399 0.0 0.00449"/>
    <parent link="Cat_982XE_P09"/>
    <child link="Cat_982XE_P10"/>
    <axis xyz="0 1 0"/>
  </joint>
  <link name="Cat_982XE_P10">
    <visual>
      <geometry>
        <mesh filename="package://construction_vehicles/loader/description/meshes/visual/P10.dae"/>
      </geometry>
    </visual>
    <collision>
      <geometry>
        <mesh filename="package://construction_vehicles/loader/description/meshes/collision/P10.stl"/>
      </geometry>
    </collision>
    <inertial>
      <mass value="1000.0"/>
      <inertia ixx="100.0" ixy="0.0" ixz="0.0" iyy="100.0" iyz="0.0" izz="100.0"/>
    </inertial>
  </link>
  <joint name="Cat_982XE_P011_Joint" type="continuous">
    <origin rpy="0 0 0" xyz="-0.15078 0.0 -0.77188"/>
    <parent link="Cat_982XE_P10"/>
    <child link="Cat_982XE_P11"/>
    <axis xyz="0 1 0"/>
  </joint>
  <link name="Cat_982XE_P11">
    <visual>
      <geometry>
        <mesh filename="package://construction_vehicles/loader/description/meshes/visual/P11.dae"/>
      </geometry>
    </visual>
    <collision>
      <geometry>
        <mesh filename="package://construction_vehicles/loader/description/meshes/collision/P11.stl"/>
      </geometry>
    </collision>
    <inertial>
      <mass value="1000.0"/>
      <inertia ixx="100.0" ixy="0.0" ixz="0.0" iyy="100.0" iyz="0.0" izz="100.0"/>
    </inertial>
  </link>
  <joint name="Cat_982XE_P012_Joint" type="continuous">
    <origin rpy="0 0 0" xyz="2.9386 0.0 -1.8232"/>
    <parent link="Cat_982XE_P03"/>
    <child link="Cat_982XE_P12"/>
    <axis xyz="0 1 0"/>
  </joint>
  <link name="Cat_982XE_P12">
    <visual>
      <geometry>
        <mesh filename="package://construction_vehicles/loader/description/meshes/visual/P12.dae"/>
      </geometry>
    </visual>
    <collision>
      <geometry>
        <mesh filename="package://construction_vehicles/loader/description/meshes/collision/P12.stl"/>
      </geometry>
    </collision>
    <inertial>
      <mass value="1000.0"/>
      <inertia ixx="100.0" ixy="0.0" ixz="0.0" iyy="100.0" iyz="0.0" izz="100.0"/>
    </inertial>
  </link>
  <joint name="Cat_982XE_P013_Joint" type="continuous">
    <origin rpy="0 0 0" xyz="-0.700314 0.68091 2.83828"/>
    <parent link="Cat_982XE_P01"/>
    <child link="Cat_982XE_P13"/>
    <axis xyz="0 0 1"/>
  </joint>
  <link name="Cat_982XE_P13">
    <visual>
      <geometry>
        <mesh filename="package://construction_vehicles/loader/description/meshes/visual/P13.dae"/>
      </geometry>
    </visual>
    <collision>
      <geometry>
        <mesh filename="package://construction_vehicles/loader/description/meshes/collision/P13.stl"/>
      </geometry>
    </collision>
    <inertial>
      <mass value="1000.0"/>
      <inertia ixx="100.0" ixy="0.0" ixz="0.0" iyy="100.0" iyz="0.0" izz="100.0"/>
    </inertial>
  </link>
  <joint name="Cat_982XE_P014_Joint" type="fixed">
    <origin rpy="0 0 0" xyz="-2.58025 0.0 0.941297"/>
    <parent link="Cat_982XE_P01"/>
    <child link="Cat_982XE_P14"/>
  </joint>
  <link name="Cat_982XE_P14">
    <visual>
      <geometry>
        <mesh filename="package://construction_vehicles/loader/description/meshes/visual/P14.dae"/>
      </geometry>
    </visual>
    <collision>
      <origin rpy="1.5707963267948966 0 0" xyz="0.0 0.0 0.0"/>
      <geometry>
        <cylinder length="1.858738" radius="0.150405"/>
      </geometry>
    </collision>
    <inertial>
      <mass value="1000.0"/>
      <inertia ixx="100.0" ixy="0.0" ixz="0.0" iyy="100.0" iyz="0.0" izz="100.0"/>
    </inertial>
  </link>
  <joint name="Cat_982XE_P015_Joint" type="continuous">
    <origin rpy="0 0 0" xyz="0.0 1.4457 0.0"/>
    <parent link="Cat_982XE_P14"/>
    <child link="Cat_982XE_P15"/>
    <axis xyz="0 1 0"/>
  </joint>
  <link name="Cat_982XE_P15">
    <visual>
      <geometry>
        <mesh filename="package://construction_vehicles/loader/description/meshes/visual/P15.dae"/>
      </geometry>
    </visual>
    <collision>
      <origin rpy="1.5707963267948966 0 0" xyz="0.0 -0.10213 0.0"/>
      <geometry>
        <cylinder length="0.817806" radius="0.934162"/>
      </geometry>
    </collision>
    <inertial>
      <mass value="1000.0"/>
      <inertia ixx="100.0" ixy="0.0" ixz="0.0" iyy="100.0" iyz="0.0" izz="100.0"/>
    </inertial>
  </link>
  <joint name="Cat_982XE_P016_Joint" type="continuous">
    <origin rpy="0 0 0" xyz="0.0 -1.4457 0.0"/>
    <parent link="Cat_982XE_P14"/>
    <child link="Cat_982XE_P16"/>
    <axis xyz="0 1 0"/>
  </joint>
  <link name="Cat_982XE_P16">
    <visual>
      <geometry>
        <mesh filename="package://construction_vehicles/loader/description/meshes/visual/P16.dae"/>
      </geometry>
    </visual>
    <collision>
      <origin rpy="1.5707963267948966 0 0" xyz="0.0 0.10213 0.0"/>
      <geometry>
        <cylinder length="0.817806" radius="0.934162"/>
      </geometry>
    </collision>
    <inertial>
      <mass value="1000.0"/>
      <inertia ixx="100.0" ixy="0.0" ixz="0.0" iyy="100.0" iyz="0.0" izz="100.0"/>
    </inertial>
  </link>
  <joint name="Cat_982XE_P018_Joint" type="continuous">
    <origin rpy="0 0 0" xyz="1.8549 1.4457 -0.39222"/>
    <parent link="Cat_982XE_P02"/>
    <child link="Cat_982XE_P18"/>
    <axis xyz="0 1 0"/>
  </joint>
  <link name="Cat_982XE_P18">
    <visual>
      <geometry>
        <mesh filename="package://construction_vehicles/loader/description/meshes/visual/P15.dae"/>
      </geometry>
    </visual>
    <collision>
      <origin rpy="1.5707963267948966 0 0" xyz="0.0 -0.10213 0.0"/>
      <geometry>
        <cylinder length="0.817806" radius="0.934162"/>
      </geometry>
    </collision>
    <inertial>
      <mass value="1000.0"/>
      <inertia ixx="100.0" ixy="0.0" ixz="0.0" iyy="100.0" iyz="0.0" izz="100.0"/>
    </inertial>
  </link>
  <joint name="Cat_982XE_P019_Joint" type="continuous">
    <origin rpy="0 0 0" xyz="1.8549 -1.4457 -0.39222"/>
    <parent link="Cat_982XE_P02"/>
    <child link="Cat_982XE_P19"/>
    <axis xyz="0 1 0"/>
  </joint>
  <link name="Cat_982XE_P19">
    <visual>
      <geometry>
        <mesh filename="package://construction_vehicles/loader/description/meshes/visual/P16.dae"/>
      </geometry>
    </visual>
    <collision>
      <origin rpy="1.5707963267948966 0 0" xyz="0.0 0.10213 0.0"/>
      <geometry>
        <cylinder length="0.817806" radius="0.934162"/>
      </geometry>
    </collision>
    <inertial>
      <mass value="1000.0"/>
      <inertia ixx="100.0" ixy="0.0" ixz="0.0" iyy="100.0" iyz="0.0" izz="100.0"/>
    </inertial>
  </link>
</robot>

