<?xml version="1.0" ?>
<!-- =================================================================================== -->
<!-- |    This document was autogenerated by xacro from /home/giang/Workspace/eco_ws/wsp/src/construction_vehicles/dump_truck/description/urdf/dump_truck.urdf.xacro | -->
<!-- |    EDITING THIS FILE BY HAND IS NOT RECOMMENDED                                 | -->
<!-- =================================================================================== -->
<robot name="dump_truck">
  <link name="Cat_740_DumperChassis">
    <visual>
      <origin rpy="0 0 0" xyz="0 0 0"/>
      <geometry>
        <mesh filename="package://construction_vehicles/dump_truck/description/meshes/visual/DumperChassis.dae"/>
      </geometry>
    </visual>
  </link>
  <joint name="Cat_740_WheelRear1LeftJoint" type="continuous">
    <origin rpy="0 0 0" xyz="-2.03074 1.169 0.889"/>
    <parent link="Cat_740_DumperChassis"/>
    <child link="Cat_740_WheelRear1Left"/>
    <axis xyz="0 1 0"/>
  </joint>
  <link name="Cat_740_WheelRear1Left">
    <visual>
      <geometry>
        <mesh filename="package://construction_vehicles/dump_truck/description/meshes/visual/WheelLeft.dae"/>
      </geometry>
    </visual>
  </link>
  <joint name="Cat_740_WheelRear1RightJoint" type="continuous">
    <origin rpy="0 0 0" xyz="-2.03074 -1.169 0.889"/>
    <parent link="Cat_740_DumperChassis"/>
    <child link="Cat_740_WheelRear1Right"/>
    <axis xyz="0 1 0"/>
  </joint>
  <link name="Cat_740_WheelRear1Right">
    <visual>
      <geometry>
        <mesh filename="package://construction_vehicles/dump_truck/description/meshes/visual/WheelRight.dae"/>
      </geometry>
    </visual>
  </link>
  <joint name="Cat_740_WheelRear2LeftJoint" type="continuous">
    <origin rpy="0 0 0" xyz="-3.99134 1.169 0.889"/>
    <parent link="Cat_740_DumperChassis"/>
    <child link="Cat_740_WheelRear2Left"/>
    <axis xyz="0 1 0"/>
  </joint>
  <link name="Cat_740_WheelRear2Left">
    <visual>
      <geometry>
        <mesh filename="package://construction_vehicles/dump_truck/description/meshes/visual/WheelLeft.dae"/>
      </geometry>
    </visual>
  </link>
  <joint name="Cat_740_WheelRear2RightJoint" type="continuous">
    <origin rpy="0 0 0" xyz="-3.99134 -1.169 0.889"/>
    <parent link="Cat_740_DumperChassis"/>
    <child link="Cat_740_WheelRear2Right"/>
    <axis xyz="0 1 0"/>
  </joint>
  <link name="Cat_740_WheelRear2Right">
    <visual>
      <geometry>
        <mesh filename="package://construction_vehicles/dump_truck/description/meshes/visual/WheelRight.dae"/>
      </geometry>
    </visual>
  </link>
  <joint name="Cat_740_DumperJoint" type="continuous">
    <origin rpy="0 0 0" xyz="-4.26 0 1.555"/>
    <parent link="Cat_740_DumperChassis"/>
    <child link="Cat_740_Dumper"/>
    <axis xyz="0 -1 0"/>
  </joint>
  <link name="Cat_740_Dumper">
    <visual>
      <geometry>
        <mesh filename="package://construction_vehicles/dump_truck/description/meshes/visual/Dumper.dae"/>
      </geometry>
    </visual>
  </link>
  <joint name="Cat_740_DumperCylinderLeftJoint" type="continuous">
    <origin rpy="-0.1009 0.405 -0.311" xyz="0.185013 0.508895 1.26466"/>
    <parent link="Cat_740_DumperChassis"/>
    <child link="Cat_740_DumperCylinderLeft"/>
    <axis xyz="0 0 1"/>
  </joint>
  <link name="Cat_740_DumperCylinderLeft">
    <visual>
      <geometry>
        <mesh filename="package://construction_vehicles/dump_truck/description/meshes/visual/DumperCylinderLeftNoWires.dae"/>
      </geometry>
    </visual>
  </link>
  <joint name="Cat_740_DumperPistonLeftJoint" type="prismatic">
    <origin rpy="0 0 0" xyz="-3.0 0 0"/>
    <parent link="Cat_740_DumperCylinderLeft"/>
    <child link="Cat_740_DumperPistonLeft"/>
    <axis xyz="-1 0 0"/>
    <limit effort="1000.0" lower="0" upper="1.8" velocity="1000.0"/>
  </joint>
  <link name="Cat_740_DumperPistonLeft">
    <visual>
      <geometry>
        <mesh filename="package://construction_vehicles/dump_truck/description/meshes/visual/DumperPiston.dae"/>
      </geometry>
    </visual>
  </link>
  <joint name="Cat_740_DumperCylinderRightJoint" type="continuous">
    <origin rpy="0.1009 0.405 0.311" xyz="0.185013 -0.508895 1.26466"/>
    <parent link="Cat_740_DumperChassis"/>
    <child link="Cat_740_DumperCylinderRight"/>
    <axis xyz="0 0 1"/>
  </joint>
  <link name="Cat_740_DumperCylinderRight">
    <visual>
      <geometry>
        <mesh filename="package://construction_vehicles/dump_truck/description/meshes/visual/DumperCylinderRightNoWires.dae"/>
      </geometry>
    </visual>
  </link>
  <joint name="Cat_740_DumperPistonRightJoint" type="prismatic">
    <origin rpy="0 0 0" xyz="-3.0 0 0"/>
    <parent link="Cat_740_DumperCylinderRight"/>
    <child link="Cat_740_DumperPistonRight"/>
    <axis xyz="-1 0 0"/>
    <limit effort="1000.0" lower="0" upper="1.8" velocity="1000.0"/>
  </joint>
  <link name="Cat_740_DumperPistonRight">
    <visual>
      <geometry>
        <mesh filename="package://construction_vehicles/dump_truck/description/meshes/visual/DumperPiston.dae"/>
      </geometry>
    </visual>
  </link>
  <joint name="Cat_740_SteeringPistonLeftJoint" type="continuous">
    <origin rpy="0 0 0" xyz="0.560 0.426 0.022"/>
    <parent link="Cat_740_HeadTilt"/>
    <child link="Cat_740_SteeringPistonLeft"/>
    <axis xyz="0 0 1"/>
  </joint>
  <link name="Cat_740_SteeringPistonLeft">
    <visual>
      <geometry>
        <mesh filename="package://construction_vehicles/dump_truck/description/meshes/visual/SteeringPiston.dae"/>
      </geometry>
    </visual>
  </link>
  <joint name="Cat_740_SteeringPistonRightJoint" type="continuous">
    <origin rpy="0 0 0" xyz="0.560 -0.426 0.022"/>
    <parent link="Cat_740_HeadTilt"/>
    <child link="Cat_740_SteeringPistonRight"/>
    <axis xyz="0 0 1"/>
  </joint>
  <link name="Cat_740_SteeringPistonRight">
    <visual>
      <geometry>
        <mesh filename="package://construction_vehicles/dump_truck/description/meshes/visual/SteeringPiston.dae"/>
      </geometry>
    </visual>
  </link>
  <joint name="Cat_740_HeadTiltJoint" type="continuous">
    <origin rpy="0 0 0" xyz="0 0 1.186"/>
    <parent link="Cat_740_DumperChassis"/>
    <child link="Cat_740_HeadTilt"/>
    <axis xyz="1 0 0"/>
  </joint>
  <link name="Cat_740_HeadTilt">
    <visual>
      <geometry>
        <mesh filename="package://construction_vehicles/dump_truck/description/meshes/visual/HeadTilt.dae"/>
      </geometry>
    </visual>
  </link>
  <joint name="Cat_740_HeadJoint" type="revolute">
    <origin rpy="0 0 0" xyz="0.8543 0 0"/>
    <parent link="Cat_740_HeadTilt"/>
    <child link="Cat_740_Head"/>
    <axis xyz="0 0 1"/>
    <limit effort="1000.0" lower="-0.7853981633974483" upper="0.7853981633974483" velocity="1000.0"/>
  </joint>
  <link name="Cat_740_Head">
    <visual>
      <geometry>
        <mesh filename="package://construction_vehicles/dump_truck/description/meshes/visual/HeadNoWires.dae"/>
      </geometry>
    </visual>
  </link>
  <joint name="Cat_740_WheelFrontLeftJoint" type="continuous">
    <origin rpy="0 0 0" xyz="1.366 1.169 -0.297"/>
    <parent link="Cat_740_Head"/>
    <child link="Cat_740_WheelFrontLeft"/>
    <axis xyz="0 1 0"/>
  </joint>
  <link name="Cat_740_WheelFrontLeft">
    <visual>
      <geometry>
        <mesh filename="package://construction_vehicles/dump_truck/description/meshes/visual/WheelLeft.dae"/>
      </geometry>
    </visual>
  </link>
  <joint name="Cat_740_WheelFrontRightJoint" type="continuous">
    <origin rpy="0 0 0" xyz="1.366 -1.169 -0.297"/>
    <parent link="Cat_740_Head"/>
    <child link="Cat_740_WheelFrontRight"/>
    <axis xyz="0 1 0"/>
  </joint>
  <link name="Cat_740_WheelFrontRight">
    <visual>
      <geometry>
        <mesh filename="package://construction_vehicles/dump_truck/description/meshes/visual/WheelRight.dae"/>
      </geometry>
    </visual>
  </link>
  <joint name="Cat_740_SteeringCylinderLeftJoint" type="continuous">
    <origin rpy="0 0 0" xyz="0.788 0.425 0.020"/>
    <parent link="Cat_740_Head"/>
    <child link="Cat_740_SteeringCylinderLeft"/>
    <axis xyz="0 0 1"/>
  </joint>
  <link name="Cat_740_SteeringCylinderLeft">
    <visual>
      <geometry>
        <mesh filename="package://construction_vehicles/dump_truck/description/meshes/visual/SteeringCylinder.dae"/>
      </geometry>
    </visual>
  </link>
  <joint name="Cat_740_SteeringCylinderRightJoint" type="continuous">
    <origin rpy="0 0 0" xyz="0.788 -0.425 0.020"/>
    <parent link="Cat_740_Head"/>
    <child link="Cat_740_SteeringCylinderRight"/>
    <axis xyz="0 0 1"/>
  </joint>
  <link name="Cat_740_SteeringCylinderRight">
    <visual>
      <geometry>
        <mesh filename="package://construction_vehicles/dump_truck/description/meshes/visual/SteeringCylinder.dae"/>
      </geometry>
    </visual>
  </link>
</robot>

