<?xml version="1.0" ?>
<!-- =================================================================================== -->
<!-- |    This document was autogenerated by xacro from /home/giang/Workspace/mujoco_ws/src/construction_vehicles/excavator/description/urdf/excavator.urdf.xacro | -->
<!-- |    EDITING THIS FILE BY HAND IS NOT RECOMMENDED                                 | -->
<!-- =================================================================================== -->
<robot name="excavator">
  <link name="Cat_395_Base">
    <visual>
      <origin rpy="0 0 3.141592653589793" xyz="0.0 0.0 0.793384"/>
      <geometry>
        <mesh filename="package://construction_vehicles/excavator/description/meshes/visual/Base_Without_Wheels_Rotate_180.dae"/>
      </geometry>
    </visual>
    <collision>
      <origin rpy="0 0 0" xyz="0.068918 0.0 1.38521"/>
      <geometry>
        <box size="2.85584 4.44524 0.684194"/>
      </geometry>
    </collision>
  </link>
  <joint name="Cat_395_Track_Left_Joint" type="fixed">
    <origin rpy="0 0 0" xyz="-0.02904 -1.709747 0.764672"/>
    <parent link="Cat_395_Base"/>
    <child link="Cat_395_Track_Left"/>
  </joint>
  <link name="Cat_395_Track_Left">
    <visual>
      <geometry>
        <mesh filename="package://construction_vehicles/excavator/description/meshes/visual/Track.dae"/>
      </geometry>
    </visual>
    <collision>
      <geometry>
        <box size="6.6022 0.757722 1.57115"/>
      </geometry>
    </collision>
  </link>
  <joint name="Cat_395_Track_Right_Joint" type="fixed">
    <origin rpy="0 0 0" xyz="-0.02904 1.709747 0.764672"/>
    <parent link="Cat_395_Base"/>
    <child link="Cat_395_Track_Right"/>
  </joint>
  <link name="Cat_395_Track_Right">
    <visual>
      <geometry>
        <mesh filename="package://construction_vehicles/excavator/description/meshes/visual/Track.dae"/>
      </geometry>
    </visual>
    <collision>
      <geometry>
        <box size="6.6022 0.757722 1.57115"/>
      </geometry>
    </collision>
  </link>
  <joint name="Cat_395_Motor_Left_Joint" type="continuous">
    <origin rpy="0 0 0" xyz="2.56148 -1.8052 0.707696"/>
    <parent link="Cat_395_Base"/>
    <child link="Cat_395_Motor_Left"/>
    <axis xyz="0 -1 0"/>
  </joint>
  <link name="Cat_395_Motor_Left">
    <visual>
      <geometry>
        <mesh filename="package://construction_vehicles/excavator/description/meshes/visual/Motor_Left.dae"/>
      </geometry>
    </visual>
    <collision>
      <geometry>
        <cylinder length="0.531622" radius="0.522574"/>
      </geometry>
    </collision>
  </link>
  <joint name="Cat_395_Motor_Right_Joint" type="continuous">
    <origin rpy="0 0 0" xyz="2.56148 1.8052 0.707696"/>
    <parent link="Cat_395_Base"/>
    <child link="Cat_395_Motor_Right"/>
    <axis xyz="0 -1 0"/>
  </joint>
  <link name="Cat_395_Motor_Right">
    <visual>
      <geometry>
        <mesh filename="package://construction_vehicles/excavator/description/meshes/visual/Motor_Right.dae"/>
      </geometry>
    </visual>
    <collision>
      <geometry>
        <cylinder length="0.531622" radius="0.522574"/>
      </geometry>
    </collision>
  </link>
  <joint name="Cat_395_Wheel_Left_Joint" type="continuous">
    <origin rpy="0 0 0" xyz="-2.65099 -1.70966 0.707697"/>
    <parent link="Cat_395_Base"/>
    <child link="Cat_395_Wheel_Left"/>
    <axis xyz="0 -1 0"/>
  </joint>
  <link name="Cat_395_Wheel_Left">
    <visual>
      <geometry>
        <mesh filename="package://construction_vehicles/excavator/description/meshes/visual/Wheel.dae"/>
      </geometry>
    </visual>
    <collision>
      <geometry>
        <cylinder length="0.177212" radius="0.46"/>
      </geometry>
    </collision>
  </link>
  <joint name="Cat_395_Wheel_Right_Joint" type="continuous">
    <origin rpy="0 0 0" xyz="-2.65099 1.70966 0.707697"/>
    <parent link="Cat_395_Base"/>
    <child link="Cat_395_Wheel_Right"/>
    <axis xyz="0 -1 0"/>
  </joint>
  <link name="Cat_395_Wheel_Right">
    <visual>
      <geometry>
        <mesh filename="package://construction_vehicles/excavator/description/meshes/visual/Wheel.dae"/>
      </geometry>
    </visual>
    <collision>
      <geometry>
        <cylinder length="0.177212" radius="0.46"/>
      </geometry>
    </collision>
  </link>
  <joint name="Cat_395_Cabin_Joint" type="revolute">
    <origin rpy="0 0 0" xyz="0.15232 0.0 0.793384"/>
    <parent link="Cat_395_Base"/>
    <child link="Cat_395_Cabin"/>
    <axis xyz="0 0 1"/>
    <limit effort="1000.0" lower="-3.141592653589793" upper="3.141592653589793" velocity="1000.0"/>
  </joint>
  <link name="Cat_395_Cabin">
    <visual>
      <geometry>
        <mesh filename="package://construction_vehicles/excavator/description/meshes/visual/Cabin_No_Wires.dae"/>
      </geometry>
    </visual>
    <collision>
      <origin rpy="0 0 0" xyz="1.24333 0.0 1.98011"/>
      <geometry>
        <box size="6.92858 4.5 2.0914"/>
      </geometry>
    </collision>
  </link>
  <joint name="Cat_395_Door_Joint" type="revolute">
    <origin rpy="0 0 0" xyz="-0.9692 -1.757323 2.610876"/>
    <parent link="Cat_395_Cabin"/>
    <child link="Cat_395_Door"/>
    <axis xyz="0 0 1"/>
    <limit effort="1000.0" lower="0.0" upper="3.141592653589793" velocity="1000.0"/>
  </joint>
  <link name="Cat_395_Door">
    <visual>
      <geometry>
        <mesh filename="package://construction_vehicles/excavator/description/meshes/visual/Door.dae"/>
      </geometry>
    </visual>
    <collision>
      <geometry>
        <mesh filename="package://construction_vehicles/excavator/description/meshes/collision/Door.stl"/>
      </geometry>
    </collision>
  </link>
  <joint name="Cat_395_Boom_Joint" type="continuous">
    <origin rpy="0 0 0" xyz="-0.340 0.0 2.047"/>
    <parent link="Cat_395_Cabin"/>
    <child link="Cat_395_Boom"/>
    <axis xyz="0 1 0"/>
  </joint>
  <link name="Cat_395_Boom">
    <visual>
      <geometry>
        <mesh filename="package://construction_vehicles/excavator/description/meshes/visual/Boom_No_Wires.dae"/>
      </geometry>
    </visual>
    <collision>
      <geometry>
        <mesh filename="package://construction_vehicles/excavator/description/meshes/collision/Boom_No_Wires.stl"/>
      </geometry>
    </collision>
  </link>
  <joint name="Cat_395_Boom_Cylinder_1_Joint" type="continuous">
    <origin rpy="0 -0.593411945678072 0" xyz="-1.269 0.0 1.167"/>
    <parent link="Cat_395_Cabin"/>
    <child link="Cat_395_Boom_Cylinder_1"/>
    <axis xyz="0 1 0"/>
  </joint>
  <link name="Cat_395_Boom_Cylinder_1">
    <visual>
      <origin rpy="0 0 0" xyz="0.0 -0.506 0.0"/>
      <geometry>
        <mesh filename="package://construction_vehicles/excavator/description/meshes/visual/Boom_Cylinder_Left_1.dae"/>
      </geometry>
    </visual>
    <visual>
      <origin rpy="0 0 0" xyz="0.0 0.506 0.0"/>
      <geometry>
        <mesh filename="package://construction_vehicles/excavator/description/meshes/visual/Boom_Cylinder_Right_1.dae"/>
      </geometry>
    </visual>
    <collision>
      <origin rpy="0 0 0" xyz="0.0 -0.506 1.09389"/>
      <geometry>
        <cylinder length="2.46036" radius="0.271748"/>
      </geometry>
    </collision>
    <collision>
      <origin rpy="0 0 0" xyz="0.0 0.506 1.09389"/>
      <geometry>
        <cylinder length="2.46036" radius="0.271748"/>
      </geometry>
    </collision>
  </link>
  <joint name="Cat_395_Boom_Cylinder_2_Joint" type="prismatic">
    <origin rpy="0 0 0" xyz="0.0 0.0 4.13344"/>
    <parent link="Cat_395_Boom_Cylinder_1"/>
    <child link="Cat_395_Boom_Cylinder_2"/>
    <axis xyz="0 0 1"/>
    <limit effort="1000.0" lower="-1.70" upper="0.31" velocity="1000.0"/>
  </joint>
  <link name="Cat_395_Boom_Cylinder_2">
    <visual>
      <origin rpy="0 0 0" xyz="0.0 -0.506 0.0"/>
      <geometry>
        <mesh filename="package://construction_vehicles/excavator/description/meshes/visual/Boom_Cylinder_Left_2.dae"/>
      </geometry>
    </visual>
    <visual>
      <origin rpy="0 0 0" xyz="0.0 0.506 0.0"/>
      <geometry>
        <mesh filename="package://construction_vehicles/excavator/description/meshes/visual/Boom_Cylinder_Right_2.dae"/>
      </geometry>
    </visual>
    <collision>
      <origin rpy="0 0 0" xyz="0.0 -0.506 -1.11271"/>
      <geometry>
        <cylinder length="2.46738" radius="0.120975"/>
      </geometry>
    </collision>
    <collision>
      <origin rpy="0 0 0" xyz="0.0 0.506 -1.11271"/>
      <geometry>
        <cylinder length="2.46738" radius="0.120975"/>
      </geometry>
    </collision>
  </link>
  <joint name="Cat_395_Arm_Cylinder_1_Joint" type="continuous">
    <origin rpy="0 -1.413716694115407 0" xyz="-2.605 0.000 3.306"/>
    <parent link="Cat_395_Boom"/>
    <child link="Cat_395_Arm_Cylinder_1"/>
    <axis xyz="0 1 0"/>
  </joint>
  <link name="Cat_395_Arm_Cylinder_1">
    <visual>
      <geometry>
        <mesh filename="package://construction_vehicles/excavator/description/meshes/visual/Arm_Cylinder_1.dae"/>
      </geometry>
    </visual>
    <collision>
      <origin rpy="0 0 0" xyz="0.0 0.0 1.4316"/>
      <geometry>
        <cylinder length="3.1358" radius="0.262538"/>
      </geometry>
    </collision>
  </link>
  <joint name="Cat_395_Arm_Cylinder_2_Joint" type="prismatic">
    <origin rpy="0 0 0" xyz="0.0 0.0 4.76576"/>
    <parent link="Cat_395_Arm_Cylinder_1"/>
    <child link="Cat_395_Arm_Cylinder_2"/>
    <axis xyz="0 0 1"/>
    <limit effort="1000.0" lower="-1.6" upper="0.38" velocity="1000.0"/>
  </joint>
  <link name="Cat_395_Arm_Cylinder_2">
    <visual>
      <geometry>
        <mesh filename="package://construction_vehicles/excavator/description/meshes/visual/Arm_Cylinder_2.dae"/>
      </geometry>
    </visual>
    <collision>
      <origin rpy="0 0 0" xyz="0.0 0.0 -1.09116"/>
      <geometry>
        <cylinder length="2.42278" radius="0.120975"/>
      </geometry>
    </collision>
  </link>
  <joint name="Cat_395_Arm_Joint" type="continuous">
    <origin rpy="0 0 0" xyz="-7.002 0.000 2.732"/>
    <parent link="Cat_395_Boom"/>
    <child link="Cat_395_Arm"/>
    <axis xyz="0 1 0"/>
  </joint>
  <link name="Cat_395_Arm">
    <visual>
      <geometry>
        <mesh filename="package://construction_vehicles/excavator/description/meshes/visual/Arm.dae"/>
      </geometry>
    </visual>
    <collision>
      <geometry>
        <mesh filename="package://construction_vehicles/excavator/description/meshes/collision/Arm.stl"/>
      </geometry>
    </collision>
  </link>
  <joint name="Cat_395_Bucket_Cylinder_1_Joint" type="continuous">
    <origin rpy="0 0.15655603390389136 0" xyz="-0.999 0.000 1.120"/>
    <parent link="Cat_395_Arm"/>
    <child link="Cat_395_Bucket_Cylinder_1"/>
    <axis xyz="0 1 0"/>
  </joint>
  <link name="Cat_395_Bucket_Cylinder_1">
    <visual>
      <geometry>
        <mesh filename="package://construction_vehicles/excavator/description/meshes/visual/Bucket_Cylinder_1.dae"/>
      </geometry>
    </visual>
    <collision>
      <origin rpy="0 0 0" xyz="0.0 0.0 -1.11"/>
      <geometry>
        <cylinder length="2.49252" radius="0.173211"/>
      </geometry>
    </collision>
  </link>
  <joint name="Cat_395_Bucket_Cylinder_2_Joint" type="prismatic">
    <origin rpy="0 0 0" xyz="0.0 0.0 -3.1066"/>
    <parent link="Cat_395_Bucket_Cylinder_1"/>
    <child link="Cat_395_Bucket_Cylinder_2"/>
    <axis xyz="0 0 1"/>
    <limit effort="1000.0" lower="-0.41" upper="0.57" velocity="1000.0"/>
  </joint>
  <link name="Cat_395_Bucket_Cylinder_2">
    <visual>
      <geometry>
        <mesh filename="package://construction_vehicles/excavator/description/meshes/visual/Bucket_Cylinder_2.dae"/>
      </geometry>
    </visual>
    <collision>
      <origin rpy="0 0 0" xyz="0.0 0.0 0.583215"/>
      <geometry>
        <cylinder length="1.408384" radius="0.120975"/>
      </geometry>
    </collision>
  </link>
  <joint name="Cat_395_Part_11_Joint" type="continuous">
    <origin rpy="0 0 0" xyz="-0.599 -0.350 -2.289"/>
    <parent link="Cat_395_Arm"/>
    <child link="Cat_395_Part_11"/>
    <axis xyz="0 1 0"/>
  </joint>
  <link name="Cat_395_Part_11">
    <visual>
      <geometry>
        <mesh filename="package://construction_vehicles/excavator/description/meshes/visual/Part_11.dae"/>
      </geometry>
    </visual>
    <collision>
      <geometry>
        <mesh filename="package://construction_vehicles/excavator/description/meshes/collision/Part_11.stl"/>
      </geometry>
    </collision>
  </link>
  <joint name="Cat_395_Bucket_Joint" type="continuous">
    <origin rpy="0 0 0" xyz="-0.659 0.000 -2.843"/>
    <parent link="Cat_395_Arm"/>
    <child link="Cat_395_Bucket"/>
    <axis xyz="0 1 0"/>
  </joint>
  <link name="Cat_395_Bucket">
    <visual>
      <geometry>
        <mesh filename="package://construction_vehicles/excavator/description/meshes/visual/Bucket.dae"/>
      </geometry>
    </visual>
    <collision>
      <geometry>
        <mesh filename="package://construction_vehicles/excavator/description/meshes/collision/Bucket.stl"/>
      </geometry>
    </collision>
  </link>
  <joint name="Cat_395_Part_12_Joint" type="continuous">
    <origin rpy="0 0 0" xyz="-0.719 0.000 0.036"/>
    <parent link="Cat_395_Bucket"/>
    <child link="Cat_395_Part_12"/>
    <axis xyz="0 1 0"/>
  </joint>
  <link name="Cat_395_Part_12">
    <visual>
      <geometry>
        <mesh filename="package://construction_vehicles/excavator/description/meshes/visual/Part_12.dae"/>
      </geometry>
    </visual>
    <collision>
      <geometry>
        <mesh filename="package://construction_vehicles/excavator/description/meshes/collision/Part_12.stl"/>
      </geometry>
    </collision>
  </link>
</robot>

