<?xml version="1.0" ?>
<!-- =================================================================================== -->
<!-- |    This document was autogenerated by xacro from /home/giang/Workspace/eco_ws/wsp/src/construction_vehicles/excavator/description/urdf/excavator.urdf.xacro | -->
<!-- |    EDITING THIS FILE BY HAND IS NOT RECOMMENDED                                 | -->
<!-- =================================================================================== -->
<robot name="excavator">
  <link name="Cat_395_Base">
    <visual>
      <origin rpy="0 0 0" xyz="0.0 0.0 0.793384"/>
      <geometry>
        <mesh filename="package://construction_vehicles/excavator/description/meshes/visual/BaseWithoutWheels.dae"/>
      </geometry>
    </visual>
  </link>
  <joint name="Cat_395_TrackLeft_Joint" type="fixed">
    <origin rpy="0 0 0" xyz="-0.02904 1.709747 0.764672"/>
    <parent link="Cat_395_Base"/>
    <child link="Cat_395_TrackLeft"/>
  </joint>
  <link name="Cat_395_TrackLeft">
    <visual>
      <geometry>
        <mesh filename="package://construction_vehicles/excavator/description/meshes/visual/Track.dae"/>
      </geometry>
    </visual>
  </link>
  <joint name="Cat_395_TrackRight_Joint" type="fixed">
    <origin rpy="0 0 0" xyz="-0.02904 -1.709747 0.764672"/>
    <parent link="Cat_395_Base"/>
    <child link="Cat_395_TrackRight"/>
  </joint>
  <link name="Cat_395_TrackRight">
    <visual>
      <geometry>
        <mesh filename="package://construction_vehicles/excavator/description/meshes/visual/Track.dae"/>
      </geometry>
    </visual>
  </link>
  <joint name="Cat_395_MotorLeft_Joint" type="continuous">
    <origin rpy="0 0 0" xyz="-2.56148 1.8052 0.707696"/>
    <parent link="Cat_395_Base"/>
    <child link="Cat_395_MotorLeft"/>
    <axis xyz="0 -1 0"/>
  </joint>
  <link name="Cat_395_MotorLeft">
    <visual>
      <geometry>
        <mesh filename="package://construction_vehicles/excavator/description/meshes/visual/MotorLeft.dae"/>
      </geometry>
    </visual>
  </link>
  <joint name="Cat_395_MotorRight_Joint" type="continuous">
    <origin rpy="0 0 0" xyz="-2.56148 -1.8052 0.707696"/>
    <parent link="Cat_395_Base"/>
    <child link="Cat_395_MotorRight"/>
    <axis xyz="0 -1 0"/>
  </joint>
  <link name="Cat_395_MotorRight">
    <visual>
      <geometry>
        <mesh filename="package://construction_vehicles/excavator/description/meshes/visual/MotorRight.dae"/>
      </geometry>
    </visual>
  </link>
  <joint name="Cat_395_WheelLeft_Joint" type="continuous">
    <origin rpy="0 0 0" xyz="2.65099 1.70966 0.707697"/>
    <parent link="Cat_395_Base"/>
    <child link="Cat_395_WheelLeft"/>
    <axis xyz="0 -1 0"/>
  </joint>
  <link name="Cat_395_WheelLeft">
    <visual>
      <geometry>
        <mesh filename="package://construction_vehicles/excavator/description/meshes/visual/Wheel.dae"/>
      </geometry>
    </visual>
  </link>
  <joint name="Cat_395_WheelRight_Joint" type="continuous">
    <origin rpy="0 0 0" xyz="2.65099 -1.70966 0.707697"/>
    <parent link="Cat_395_Base"/>
    <child link="Cat_395_WheelRight"/>
    <axis xyz="0 -1 0"/>
  </joint>
  <link name="Cat_395_WheelRight">
    <visual>
      <geometry>
        <mesh filename="package://construction_vehicles/excavator/description/meshes/visual/Wheel.dae"/>
      </geometry>
    </visual>
  </link>
  <joint name="Cat_395_Cabin_Joint" type="revolute">
    <origin rpy="0 0 0" xyz="0.15232 0.0 0.793384"/>
    <parent link="Cat_395_Base"/>
    <child link="Cat_395_Cabin"/>
    <axis xyz="0 0 1"/>
    <limit effort="1000.0" lower="-3.141592653589793" upper="3.141592653589793" velocity="1000.0"/>
  </joint>
  <link name="Cat_395_Cabin">
    <visual>
      <geometry>
        <mesh filename="package://construction_vehicles/excavator/description/meshes/visual/CabinNoWires.dae"/>
      </geometry>
    </visual>
  </link>
  <joint name="Cat_395_Door_Joint" type="revolute">
    <origin rpy="0 0 0" xyz="0.9692 1.757323 2.610876"/>
    <parent link="Cat_395_Cabin"/>
    <child link="Cat_395_Door"/>
    <axis xyz="0 0 1"/>
    <limit effort="1000.0" lower="0.0" upper="3.141592653589793" velocity="1000.0"/>
  </joint>
  <link name="Cat_395_Door">
    <visual>
      <geometry>
        <mesh filename="package://construction_vehicles/excavator/description/meshes/visual/Door.dae"/>
      </geometry>
    </visual>
  </link>
  <joint name="Cat_395_Boom_Joint" type="continuous">
    <origin rpy="0 0 0" xyz="0.340 0.0 2.047"/>
    <parent link="Cat_395_Cabin"/>
    <child link="Cat_395_Boom"/>
    <axis xyz="0 1 0"/>
  </joint>
  <link name="Cat_395_Boom">
    <visual>
      <geometry>
        <mesh filename="package://construction_vehicles/excavator/description/meshes/visual/BoomNoWires.dae"/>
      </geometry>
    </visual>
  </link>
  <joint name="Cat_395_BoomCylinder1_Joint" type="continuous">
    <origin rpy="0 0.593411945678072 0" xyz="1.269 0.0 1.167"/>
    <parent link="Cat_395_Cabin"/>
    <child link="Cat_395_BoomCylinder1"/>
    <axis xyz="0 1 0"/>
  </joint>
  <link name="Cat_395_BoomCylinder1">
    <visual>
      <origin rpy="0 0 0" xyz="0.0 0.506 0.0"/>
      <geometry>
        <mesh filename="package://construction_vehicles/excavator/description/meshes/visual/BoomCylinderLeft1.dae"/>
      </geometry>
    </visual>
    <visual>
      <origin rpy="0 0 0" xyz="0.0 -0.506 0.0"/>
      <geometry>
        <mesh filename="package://construction_vehicles/excavator/description/meshes/visual/BoomCylinderRight1.dae"/>
      </geometry>
    </visual>
  </link>
  <joint name="Cat_395_BoomCylinder2_Joint" type="prismatic">
    <origin rpy="0 0 0" xyz="0.0 0.0 4.13344"/>
    <parent link="Cat_395_BoomCylinder1"/>
    <child link="Cat_395_BoomCylinder2"/>
    <axis xyz="0 0 1"/>
    <limit effort="1000.0" lower="-1.70" upper="0.31" velocity="1000.0"/>
  </joint>
  <link name="Cat_395_BoomCylinder2">
    <visual>
      <origin rpy="0 0 0" xyz="0.0 0.506 0.0"/>
      <geometry>
        <mesh filename="package://construction_vehicles/excavator/description/meshes/visual/BoomCylinderLeft2.dae"/>
      </geometry>
    </visual>
    <visual>
      <origin rpy="0 0 0" xyz="0.0 -0.506 0.0"/>
      <geometry>
        <mesh filename="package://construction_vehicles/excavator/description/meshes/visual/BoomCylinderRight2.dae"/>
      </geometry>
    </visual>
  </link>
  <joint name="Cat_395_ArmCylinder1_Joint" type="continuous">
    <origin rpy="0 1.413716694115407 0" xyz="2.605 0.000 3.306"/>
    <parent link="Cat_395_Boom"/>
    <child link="Cat_395_ArmCylinder1"/>
    <axis xyz="0 1 0"/>
  </joint>
  <link name="Cat_395_ArmCylinder1">
    <visual>
      <geometry>
        <mesh filename="package://construction_vehicles/excavator/description/meshes/visual/ArmCylinder1.dae"/>
      </geometry>
    </visual>
  </link>
  <joint name="Cat_395_ArmCylinder2_Joint" type="prismatic">
    <origin rpy="0 0 0" xyz="0.0 0.0 4.76576"/>
    <parent link="Cat_395_ArmCylinder1"/>
    <child link="Cat_395_ArmCylinder2"/>
    <axis xyz="0 0 1"/>
    <limit effort="1000.0" lower="-1.6" upper="0.38" velocity="1000.0"/>
  </joint>
  <link name="Cat_395_ArmCylinder2">
    <visual>
      <geometry>
        <mesh filename="package://construction_vehicles/excavator/description/meshes/visual/ArmCylinder2.dae"/>
      </geometry>
    </visual>
  </link>
  <joint name="Cat_395_Arm_Joint" type="continuous">
    <origin rpy="0 0 0" xyz="7.002 0.000 2.732"/>
    <parent link="Cat_395_Boom"/>
    <child link="Cat_395_Arm"/>
    <axis xyz="0 1 0"/>
  </joint>
  <link name="Cat_395_Arm">
    <visual>
      <geometry>
        <mesh filename="package://construction_vehicles/excavator/description/meshes/visual/Arm.dae"/>
      </geometry>
    </visual>
  </link>
  <joint name="Cat_395_BucketCylinder1_Joint" type="continuous">
    <origin rpy="0 -0.15655603390389136 0" xyz="0.999 0.000 1.120"/>
    <parent link="Cat_395_Arm"/>
    <child link="Cat_395_BucketCylinder1"/>
    <axis xyz="0 1 0"/>
  </joint>
  <link name="Cat_395_BucketCylinder1">
    <visual>
      <geometry>
        <mesh filename="package://construction_vehicles/excavator/description/meshes/visual/BucketCylinder1.dae"/>
      </geometry>
    </visual>
  </link>
  <joint name="Cat_395_BucketCylinder2_Joint" type="prismatic">
    <origin rpy="0 0 0" xyz="0.0 0.0 -3.1066"/>
    <parent link="Cat_395_BucketCylinder1"/>
    <child link="Cat_395_BucketCylinder2"/>
    <axis xyz="0 0 1"/>
    <limit effort="1000.0" lower="-0.41" upper="0.57" velocity="1000.0"/>
  </joint>
  <link name="Cat_395_BucketCylinder2">
    <visual>
      <geometry>
        <mesh filename="package://construction_vehicles/excavator/description/meshes/visual/BucketCylinder2.dae"/>
      </geometry>
    </visual>
  </link>
  <joint name="Cat_395_Part11_Joint" type="continuous">
    <origin rpy="0 0 0" xyz="0.599 0.350 -2.289"/>
    <parent link="Cat_395_Arm"/>
    <child link="Cat_395_Part11"/>
    <axis xyz="0 1 0"/>
  </joint>
  <link name="Cat_395_Part11">
    <visual>
      <geometry>
        <mesh filename="package://construction_vehicles/excavator/description/meshes/visual/Part11.dae"/>
      </geometry>
    </visual>
  </link>
  <joint name="Cat_395_Bucket_Joint" type="continuous">
    <origin rpy="0 0 0" xyz="0.659 0.0 -2.843"/>
    <parent link="Cat_395_Arm"/>
    <child link="Cat_395_Bucket"/>
    <axis xyz="0 1 0"/>
  </joint>
  <link name="Cat_395_Bucket">
    <visual>
      <geometry>
        <mesh filename="package://construction_vehicles/excavator/description/meshes/visual/Bucket.dae"/>
      </geometry>
    </visual>
  </link>
  <joint name="Cat_395_Part12_Joint" type="continuous">
    <origin rpy="0 0 0" xyz="0.719 0.0 0.036"/>
    <parent link="Cat_395_Bucket"/>
    <child link="Cat_395_Part12"/>
    <axis xyz="0 1 0"/>
  </joint>
  <link name="Cat_395_Part12">
    <visual>
      <geometry>
        <mesh filename="package://construction_vehicles/excavator/description/meshes/visual/Part12.dae"/>
      </geometry>
    </visual>
  </link>
</robot>

