<?xml version="1.0" encoding="utf-8"?>
<robot xmlns:xacro="http://www.ros.org/wiki/xacro" name="excavator">
  <xacro:macro name="excavator" params="prefix:=''">
    <link name="${prefix}Base">
      <visual>
        <origin xyz="0.0 0.0 0.793384" rpy="0 0 0" />
        <geometry>
          <mesh filename="package://construction_vehicles/excavator/description/meshes/visual/BaseWithoutWheels.dae" />
        </geometry>
      </visual>
    </link>

    <joint name="${prefix}TrackLeft_Joint" type="fixed">
      <origin xyz="-0.02904 1.709747 0.764672" rpy="0 0 0" />
      <parent link="${prefix}Base" />
      <child link="${prefix}TrackLeft" />
    </joint>
    <link name="${prefix}TrackLeft">
      <visual>
        <geometry>
          <mesh filename="package://construction_vehicles/excavator/description/meshes/visual/Track.dae" />
        </geometry>
      </visual>
    </link>

    <joint name="${prefix}TrackRight_Joint" type="fixed">
      <origin xyz="-0.02904 -1.709747 0.764672" rpy="0 0 0" />
      <parent link="${prefix}Base" />
      <child link="${prefix}TrackRight" />
    </joint>
    <link name="${prefix}TrackRight">
      <visual>
        <geometry>
          <mesh filename="package://construction_vehicles/excavator/description/meshes/visual/Track.dae" />
        </geometry>
      </visual>
    </link>

    <joint name="${prefix}MotorLeft_Joint" type="continuous">
      <origin xyz="-2.56148 1.8052 0.707696" rpy="0 0 0" />
      <parent link="${prefix}Base" />
      <child link="${prefix}MotorLeft" />
      <axis xyz="0 -1 0" />
    </joint>
    <link name="${prefix}MotorLeft">
      <visual>
        <geometry>
          <mesh filename="package://construction_vehicles/excavator/description/meshes/visual/MotorLeft.dae" />
        </geometry>
      </visual>
    </link>

    <joint name="${prefix}MotorRight_Joint" type="continuous">
      <origin xyz="-2.56148 -1.8052 0.707696" rpy="0 0 0" />
      <parent link="${prefix}Base" />
      <child link="${prefix}MotorRight" />
      <axis xyz="0 -1 0" />
    </joint>
    <link name="${prefix}MotorRight">
      <visual>
        <geometry>
          <mesh filename="package://construction_vehicles/excavator/description/meshes/visual/MotorRight.dae" />
        </geometry>
      </visual>
    </link>

    <joint name="${prefix}WheelLeft_Joint" type="continuous">
      <origin xyz="2.65099 1.70966 0.707697" rpy="0 0 0" />
      <parent link="${prefix}Base" />
      <child link="${prefix}WheelLeft" />
      <axis xyz="0 -1 0" />
    </joint>
    <link name="${prefix}WheelLeft">
      <visual>
        <geometry>
          <mesh filename="package://construction_vehicles/excavator/description/meshes/visual/Wheel.dae" />
        </geometry>
      </visual>
    </link>

    <joint name="${prefix}WheelRight_Joint" type="continuous">
      <origin xyz="2.65099 -1.70966 0.707697" rpy="0 0 0" />
      <parent link="${prefix}Base" />
      <child link="${prefix}WheelRight" />
      <axis xyz="0 -1 0" />
    </joint>
    <link name="${prefix}WheelRight">
      <visual>
        <geometry>
          <mesh filename="package://construction_vehicles/excavator/description/meshes/visual/Wheel.dae" />
        </geometry>
      </visual>
    </link>

    <joint name="Cat_395_Cabin_Joint" type="revolute">
      <origin xyz="0.15232 0.0 0.793384" rpy="0 0 0" />
      <parent link="Cat_395_Base" />
      <child link="Cat_395_Cabin" />
      <axis xyz="0 0 1" />
      <limit effort="1000.0" lower="${-pi}" upper="${pi}" velocity="1000.0" />
    </joint>
    <link name="${prefix}Cabin">
      <visual>
        <geometry>
          <mesh filename="package://construction_vehicles/excavator/description/meshes/visual/CabinNoWires.dae" />
        </geometry>
      </visual>
    </link>

    <joint name="${prefix}Door_Joint" type="revolute">
      <origin xyz="0.9692 1.757323 2.610876" rpy="0 0 0" />
      <parent link="${prefix}Cabin" />
      <child link="${prefix}Door" />
      <axis xyz="0 0 1" />
      <limit effort="1000.0" lower="0.0" upper="${pi}" velocity="1000.0" />
    </joint>
    <link name="${prefix}Door">
      <visual>
        <geometry>
          <mesh filename="package://construction_vehicles/excavator/description/meshes/visual/Door.dae" />
        </geometry>
      </visual>
    </link>

    <joint name="${prefix}Boom_Joint" type="continuous">
      <origin xyz="0.340 0.0 2.047" rpy="0 0 0" />
      <parent link="${prefix}Cabin" />
      <child link="${prefix}Boom" />
      <axis xyz="0 1 0" />
    </joint>
    <link name="${prefix}Boom">
      <visual>
        <geometry>
          <mesh filename="package://construction_vehicles/excavator/description/meshes/visual/BoomNoWires.dae" />
        </geometry>
      </visual>
    </link>

    <joint name="${prefix}BoomCylinder1_Joint" type="continuous">
      <origin xyz="1.269 0.0 1.167" rpy="0 ${34/180 * pi} 0" />
      <parent link="${prefix}Cabin" />
      <child link="${prefix}BoomCylinder1" />
      <axis xyz="0 1 0" />
    </joint>
    <link name="${prefix}BoomCylinder1">
      <visual>
        <origin xyz="0.0 0.506 0.0" rpy="0 0 0" />
        <geometry>
          <mesh filename="package://construction_vehicles/excavator/description/meshes/visual/BoomCylinderLeft1.dae" />
        </geometry>
      </visual>
      <visual>
        <origin xyz="0.0 -0.506 0.0" rpy="0 0 0" />
        <geometry>
          <mesh filename="package://construction_vehicles/excavator/description/meshes/visual/BoomCylinderRight1.dae" />
        </geometry>
      </visual>
    </link>

    <joint name="${prefix}BoomCylinder2_Joint" type="prismatic">
      <origin xyz="0.0 0.0 4.13344" rpy="0 0 0" />
      <parent link="${prefix}BoomCylinder1" />
      <child link="${prefix}BoomCylinder2" />
      <axis xyz="0 0 1" />
      <limit lower="-1.70" upper="0.31" effort="1000.0" velocity="1000.0" />
    </joint>
    <link name="${prefix}BoomCylinder2">
      <visual>
        <origin xyz="0.0 0.506 0.0" rpy="0 0 0" />
        <geometry>
          <mesh filename="package://construction_vehicles/excavator/description/meshes/visual/BoomCylinderLeft2.dae" />
        </geometry>
      </visual>
      <visual>
        <origin xyz="0.0 -0.506 0.0" rpy="0 0 0" />
        <geometry>
          <mesh filename="package://construction_vehicles/excavator/description/meshes/visual/BoomCylinderRight2.dae" />
        </geometry>
      </visual>
    </link>

    <joint name="${prefix}ArmCylinder1_Joint" type="continuous">
      <origin xyz="2.605 0.000 3.306" rpy="0 ${81/180 * pi} 0" />
      <parent link="${prefix}Boom" />
      <child link="${prefix}ArmCylinder1" />
      <axis xyz="0 1 0" />
    </joint>
    <link name="${prefix}ArmCylinder1">
      <visual>
        <geometry>
          <mesh filename="package://construction_vehicles/excavator/description/meshes/visual/ArmCylinder1.dae" />
        </geometry>
      </visual>
    </link>

    <joint name="${prefix}ArmCylinder2_Joint" type="prismatic">
      <origin xyz="0.0 0.0 4.76576" rpy="0 0 0" />
      <parent link="${prefix}ArmCylinder1" />
      <child link="${prefix}ArmCylinder2" />
      <axis xyz="0 0 1" />
      <limit lower="-1.6" upper="0.38" effort="1000.0" velocity="1000.0" />
    </joint>
    <link name="${prefix}ArmCylinder2">
      <visual>
        <geometry>
          <mesh filename="package://construction_vehicles/excavator/description/meshes/visual/ArmCylinder2.dae" />
        </geometry>
      </visual>
    </link>

    <joint name="${prefix}Arm_Joint" type="continuous">
      <origin xyz="7.002 0.000 2.732" rpy="0 0 0" />
      <parent link="${prefix}Boom" />
      <child link="${prefix}Arm" />
      <axis xyz="0 1 0" />
    </joint>
    <link name="${prefix}Arm">
      <visual>
        <geometry>
          <mesh filename="package://construction_vehicles/excavator/description/meshes/visual/Arm.dae" />
        </geometry>
      </visual>
    </link>

    <joint name="${prefix}BucketCylinder1_Joint" type="continuous">
      <origin xyz="0.999 0.000 1.120" rpy="0 ${-8.97/180 * pi} 0" />
      <parent link="${prefix}Arm" />
      <child link="${prefix}BucketCylinder1" />
      <axis xyz="0 1 0" />
    </joint>
    <link name="${prefix}BucketCylinder1">
      <visual>
        <geometry>
          <mesh filename="package://construction_vehicles/excavator/description/meshes/visual/BucketCylinder1.dae" />
        </geometry>
      </visual>
    </link>

    <joint name="${prefix}BucketCylinder2_Joint" type="prismatic">
      <origin xyz="0.0 0.0 -3.1066" rpy="0 0 0" />
      <parent link="${prefix}BucketCylinder1" />
      <child link="${prefix}BucketCylinder2" />
      <axis xyz="0 0 1" />
      <limit lower="-0.41" upper="0.57" effort="1000.0" velocity="1000.0" />
    </joint>
    <link name="${prefix}BucketCylinder2">
      <visual>
        <geometry>
          <mesh filename="package://construction_vehicles/excavator/description/meshes/visual/BucketCylinder2.dae" />
        </geometry>
      </visual>
    </link>

    <joint name="${prefix}Part11_Joint" type="continuous">
      <origin xyz="0.599 0.350 -2.289" rpy="0 0 0" />
      <parent link="${prefix}Arm" />
      <child link="${prefix}Part11" />
      <axis xyz="0 1 0" />
    </joint>
    <link name="${prefix}Part11">
      <visual>
        <geometry>
          <mesh filename="package://construction_vehicles/excavator/description/meshes/visual/Part11.dae" />
        </geometry>
      </visual>
    </link>

    <joint name="${prefix}Bucket_Joint" type="continuous">
      <origin xyz="0.659 0.0 -2.843" rpy="0 0 0" />
      <parent link="${prefix}Arm" />
      <child link="${prefix}Bucket" />
      <axis xyz="0 1 0" />
    </joint>
    <link name="${prefix}Bucket">
      <visual>
        <geometry>
          <mesh filename="package://construction_vehicles/excavator/description/meshes/visual/Bucket.dae" />
        </geometry>
      </visual>
    </link>

    <joint name="${prefix}Part12_Joint" type="continuous">
      <origin xyz="0.719 0.0 0.036" rpy="0 0 0" />
      <parent link="${prefix}Bucket" />
      <child link="${prefix}Part12" />
      <axis xyz="0 1 0" />
    </joint>
    <link name="${prefix}Part12">
      <visual>
        <geometry>
          <mesh filename="package://construction_vehicles/excavator/description/meshes/visual/Part12.dae" />
        </geometry>
      </visual>
    </link>

  </xacro:macro>
</robot>