<?xml version="1.0" ?>
<!-- =================================================================================== -->
<!-- |    This document was autogenerated by xacro from /home/giang/Workspace/eco_ws/src/construction_vehicles/caterpillar/description/urdf/caterpillar.urdf.xacro | -->
<!-- |    EDITING THIS FILE BY HAND IS NOT RECOMMENDED                                 | -->
<!-- =================================================================================== -->
<robot name="caterpillar">
  <link name="Caterpillar_797_Main">
    <visual>
      <origin rpy="0 0 0" xyz="5.98719 0.0 3.1686"/>
      <geometry>
        <mesh filename="package://construction_vehicles/caterpillar/description/meshes/visual/Main.dae"/>
      </geometry>
    </visual>
  </link>
  <joint name="Caterpillar_797_FrontLeftSwivel_Joint" type="revolute">
    <origin rpy="0 0 0" xyz="3.56191 1.61062 1.84622"/>
    <parent link="Caterpillar_797_Main"/>
    <child link="Caterpillar_797_FrontLeftSwivel"/>
    <axis xyz="0 0 1"/>
    <limit effort="1000.0" lower="-0.7853981633974483" upper="0.7853981633974483" velocity="1000.0"/>
  </joint>
  <link name="Caterpillar_797_FrontLeftSwivel">
    <visual>
      <geometry>
        <mesh filename="package://construction_vehicles/caterpillar/description/meshes/visual/FrontLeftSwivel.dae"/>
      </geometry>
    </visual>
  </link>
  <joint name="Caterpillar_797_FrontLeftWheel_Joint" type="continuous">
    <origin rpy="0 0 0" xyz="0.0 1.61918 -0.003"/>
    <parent link="Caterpillar_797_FrontLeftSwivel"/>
    <child link="Caterpillar_797_FrontLeftWheel"/>
    <axis xyz="0 1 0"/>
  </joint>
  <link name="Caterpillar_797_FrontLeftWheel">
    <visual>
      <geometry>
        <mesh filename="package://construction_vehicles/caterpillar/description/meshes/visual/FrontLeftWheel.dae"/>
      </geometry>
    </visual>
  </link>
  <joint name="Caterpillar_797_FrontRightSwivel_Joint" type="revolute">
    <origin rpy="0 0 0" xyz="3.56191 -1.61418 1.84622"/>
    <parent link="Caterpillar_797_Main"/>
    <child link="Caterpillar_797_FrontRightSwivel"/>
    <axis xyz="0 0 1"/>
    <limit effort="1000.0" lower="-0.7853981633974483" upper="0.7853981633974483" velocity="1000.0"/>
  </joint>
  <link name="Caterpillar_797_FrontRightSwivel">
    <visual>
      <geometry>
        <mesh filename="package://construction_vehicles/caterpillar/description/meshes/visual/FrontRightSwivel.dae"/>
      </geometry>
    </visual>
  </link>
  <joint name="Caterpillar_797_FrontRightWheel_Joint" type="continuous">
    <origin rpy="0 0 0" xyz="0.0 -1.61918 -0.003"/>
    <parent link="Caterpillar_797_FrontRightSwivel"/>
    <child link="Caterpillar_797_FrontRightWheel"/>
    <axis xyz="0 1 0"/>
  </joint>
  <link name="Caterpillar_797_FrontRightWheel">
    <visual>
      <geometry>
        <mesh filename="package://construction_vehicles/caterpillar/description/meshes/visual/FrontRightWheel.dae"/>
      </geometry>
    </visual>
  </link>
  <joint name="Caterpillar_797_RearLeftWheel_Joint" type="continuous">
    <origin rpy="0 0 0" xyz="-3.56191 2.77434 1.84289"/>
    <parent link="Caterpillar_797_Main"/>
    <child link="Caterpillar_797_RearLeftWheel"/>
    <axis xyz="0 1 0"/>
  </joint>
  <link name="Caterpillar_797_RearLeftWheel">
    <visual>
      <geometry>
        <mesh filename="package://construction_vehicles/caterpillar/description/meshes/visual/RearLeftWheel.dae"/>
      </geometry>
    </visual>
  </link>
  <joint name="Caterpillar_797_RearRightWheel_Joint" type="continuous">
    <origin rpy="0 0 0" xyz="-3.56191 -2.77434 1.84289"/>
    <parent link="Caterpillar_797_Main"/>
    <child link="Caterpillar_797_RearRightWheel"/>
    <axis xyz="0 1 0"/>
  </joint>
  <link name="Caterpillar_797_RearRightWheel">
    <visual>
      <geometry>
        <mesh filename="package://construction_vehicles/caterpillar/description/meshes/visual/RearRightWheel.dae"/>
      </geometry>
    </visual>
  </link>
  <joint name="Caterpillar_797_Push1_Joint" type="continuous">
    <origin rpy="0 -0.09773843811168245 0" xyz="-0.9743 -0.00178 1.54515"/>
    <parent link="Caterpillar_797_Main"/>
    <child link="Caterpillar_797_Push1"/>
    <axis xyz="0 1 0"/>
  </joint>
  <link name="Caterpillar_797_Push1">
    <visual>
      <geometry>
        <mesh filename="package://construction_vehicles/caterpillar/description/meshes/visual/Push1.dae"/>
      </geometry>
    </visual>
  </link>
  <joint name="Caterpillar_797_Push3_Joint" type="prismatic">
    <origin rpy="0 0 0" xyz="0.0 0.0 2.18448"/>
    <parent link="Caterpillar_797_Push1"/>
    <child link="Caterpillar_797_Push3"/>
    <axis xyz="0 0 1"/>
    <limit effort="1000.0" lower="0.0" upper="1.4" velocity="1000.0"/>
  </joint>
  <link name="Caterpillar_797_Push3">
    <visual>
      <geometry>
        <mesh filename="package://construction_vehicles/caterpillar/description/meshes/visual/Push3.dae"/>
      </geometry>
    </visual>
  </link>
  <joint name="Caterpillar_797_BackPart_Joint" type="continuous">
    <origin rpy="0 0 0" xyz="-4.24691 -0.00178 3.87289"/>
    <parent link="Caterpillar_797_Main"/>
    <child link="Caterpillar_797_BackPart"/>
    <axis xyz="0 1 0"/>
  </joint>
  <link name="Caterpillar_797_BackPart">
    <visual>
      <geometry>
        <mesh filename="package://construction_vehicles/caterpillar/description/meshes/visual/BackPart.dae"/>
      </geometry>
    </visual>
  </link>
  <joint name="Caterpillar_797_Cabin_Joint" type="fixed">
    <origin rpy="0 0 0" xyz="3.590641 2.436792 5.43797"/>
    <parent link="Caterpillar_797_Main"/>
    <child link="Caterpillar_797_Cabin"/>
  </joint>
  <link name="Caterpillar_797_Cabin">
    <visual>
      <geometry>
        <mesh filename="package://construction_vehicles/caterpillar/description/meshes/visual/Cabin.dae"/>
      </geometry>
    </visual>
  </link>
  <joint name="Caterpillar_797_Chair_Joint" type="fixed">
    <origin rpy="0 0 0" xyz="0.074 0.0 -0.034"/>
    <parent link="Caterpillar_797_Cabin"/>
    <child link="Caterpillar_797_Chair"/>
  </joint>
  <link name="Caterpillar_797_Chair">
    <visual>
      <geometry>
        <mesh filename="package://construction_vehicles/caterpillar/description/meshes/visual/Chair.dae"/>
      </geometry>
    </visual>
  </link>
  <joint name="Caterpillar_797_Cockpit_Joint" type="fixed">
    <origin rpy="0 0 0" xyz="0.0 0.0 0.0"/>
    <parent link="Caterpillar_797_Cabin"/>
    <child link="Caterpillar_797_Cockpit"/>
  </joint>
  <link name="Caterpillar_797_Cockpit">
    <visual>
      <geometry>
        <mesh filename="package://construction_vehicles/caterpillar/description/meshes/visual/Cockpit.dae"/>
      </geometry>
    </visual>
  </link>
  <joint name="Caterpillar_797_DoorRight_Joint" type="revolute">
    <origin rpy="0 0 0" xyz="-0.071 -0.873 -0.082"/>
    <parent link="Caterpillar_797_Cabin"/>
    <child link="Caterpillar_797_DoorRight"/>
    <axis xyz="0 0 -1"/>
    <limit effort="1000.0" lower="0.0" upper="1.5707963267948966" velocity="1000.0"/>
  </joint>
  <link name="Caterpillar_797_DoorRight">
    <visual>
      <geometry>
        <mesh filename="package://construction_vehicles/caterpillar/description/meshes/visual/DoorRight.dae"/>
      </geometry>
    </visual>
  </link>
  <joint name="Caterpillar_797_DoorLeft_Joint" type="revolute">
    <origin rpy="0 0 0" xyz="3.519751 3.30997 6.02837"/>
    <parent link="Caterpillar_797_Main"/>
    <child link="Caterpillar_797_DoorLeft"/>
    <axis xyz="0 0 1"/>
    <limit effort="1000.0" lower="0.0" upper="1.5707963267948966" velocity="1000.0"/>
  </joint>
  <link name="Caterpillar_797_DoorLeft">
    <visual>
      <geometry>
        <mesh filename="package://construction_vehicles/caterpillar/description/meshes/visual/DoorLeft.dae"/>
      </geometry>
    </visual>
  </link>
</robot>

